<sdf version='1.7'>
  <model name='parc_robot_v2'>
    <link name='base_footprint'>
      <inertial>
        <pose>0.00504 0.000106 0.242006 0 -0 0</pose>
        <mass>41.1129</mass>
        <inertia>
          <ixx>2.47066</ixx>
          <ixy>-0.000972787</ixy>
          <ixz>0.0111346</ixz>
          <iyy>5.37438</iyy>
          <iyz>-0.000564458</iyz>
          <izz>3.55842</izz>
        </inertia>
      </inertial>
      <collision name='base_footprint_fixed_joint_lump__base_collision_collision'>
        <pose>0 0 0.24279 0 -0 0</pose>
        <geometry>
          <box>
            <size>0.925 0.38 0.21</size>
          </box>
        </geometry>
      </collision>
      <collision name='base_footprint_fixed_joint_lump__base_link_collision_1'>
        <pose>0 0 0.26979 0 -0 0</pose>
        <geometry>
          <box>
            <size>0.154167 0.627 0.07</size>
          </box>
        </geometry>
      </collision>
      <collision name='base_footprint_fixed_joint_lump__collision_collision_2'>
        <pose>0.7 0 0.02479 0 -0 0</pose>
        <geometry>
          <mesh>
            <scale>0.001 0.001 0.001</scale>
            <uri>model://parc_robot_description/meshes/enclosure.dae</uri>
          </mesh>
        </geometry>
      </collision>
      <collision name='base_footprint_fixed_joint_lump__left_camera_collision_3'>
        <pose>0 0.242 0.86979 0 -0 1.5708</pose>
        <geometry>
          <mesh>
            <scale>1 1 1</scale>
            <uri>model://parc_robot_description/meshes/ZED2.dae</uri>
          </mesh>
        </geometry>
        <surface>
          <contact>
            <ode/>
          </contact>
          <friction>
            <ode/>
          </friction>
        </surface>
      </collision>
      <collision name='base_footprint_fixed_joint_lump__right_camera_collision_4'>
        <pose>0 -0.241 0.86979 0 0 -1.5708</pose>
        <geometry>
          <mesh>
            <scale>1 1 1</scale>
            <uri>model://parc_robot_description/meshes/ZED2.dae</uri>
          </mesh>
        </geometry>
        <surface>
          <contact>
            <ode/>
          </contact>
          <friction>
            <ode/>
          </friction>
        </surface>
      </collision>
      <collision name='base_footprint_fixed_joint_lump__ydlidar_link_collision_5'>
        <pose>0.25 0 0.41479 0 -0 0</pose>
        <geometry>
          <mesh>
            <scale>1 1 1</scale>
            <uri>model://parc_robot_description/meshes/ydlidar.dae</uri>
          </mesh>
        </geometry>
        <surface>
          <contact>
            <ode/>
          </contact>
          <friction>
            <ode/>
          </friction>
        </surface>
      </collision>
      <collision name='base_footprint_fixed_joint_lump__zed2_camera_center_collision_6'>
        <pose>0.36 0 0.34479 0 -0 0</pose>
        <geometry>
          <mesh>
            <scale>1 1 1</scale>
            <uri>model://parc_robot_description/meshes/ZED2.dae</uri>
          </mesh>
        </geometry>
        <surface>
          <contact>
            <ode/>
          </contact>
          <friction>
            <ode/>
          </friction>
        </surface>
      </collision>
      <visual name='base_footprint_fixed_joint_lump__base_link_visual'>
        <pose>0 0 0.23479 0 -0 0</pose>
        <geometry>
          <mesh>
            <scale>1 1 1</scale>
            <uri>model://parc_robot_description/meshes/base_link.dae</uri>
          </mesh>
        </geometry>
      </visual>
      <visual name='base_footprint_fixed_joint_lump__visual_visual_1'>
        <pose>0.7 0 0.02479 0 -0 0</pose>
        <geometry>
          <mesh>
            <scale>0.001 0.001 0.001</scale>
            <uri>model://parc_robot_description/meshes/enclosure.dae</uri>
          </mesh>
        </geometry>
      </visual>
      <visual name='base_footprint_fixed_joint_lump__left_camera_visual_2'>
        <pose>0 0.242 0.86979 0 -0 1.5708</pose>
        <geometry>
          <mesh>
            <scale>1 1 1</scale>
            <uri>model://parc_robot_description/meshes/ZED2.dae</uri>
          </mesh>
        </geometry>
      </visual>
      <visual name='base_footprint_fixed_joint_lump__right_camera_visual_3'>
        <pose>0 -0.241 0.86979 0 0 -1.5708</pose>
        <geometry>
          <mesh>
            <scale>1 1 1</scale>
            <uri>model://parc_robot_description/meshes/ZED2.dae</uri>
          </mesh>
        </geometry>
      </visual>
      <visual name='base_footprint_fixed_joint_lump__ydlidar_link_visual_4'>
        <pose>0.25 0 0.41479 0 -0 0</pose>
        <geometry>
          <mesh>
            <scale>1 1 1</scale>
            <uri>model://parc_robot_description/meshes/ydlidar.dae</uri>
          </mesh>
        </geometry>
      </visual>
      <visual name='base_footprint_fixed_joint_lump__zed2_camera_center_visual_5'>
        <pose>0.36 0 0.34479 0 -0 0</pose>
        <geometry>
          <mesh>
            <scale>1 1 1</scale>
            <uri>model://parc_robot_description/meshes/ZED2.dae</uri>
          </mesh>
        </geometry>
      </visual>
      <sensor name='gps_sensor' type='gps'>
        <always_on>1</always_on>
        <update_rate>4</update_rate>
        <gps>
          <position_sensing>
            <horizontal>
              <noise type='gaussian'>
                <mean>0</mean>
                <stddev>0.001</stddev>
              </noise>
            </horizontal>
            <vertical>
              <noise type='gaussian'>
                <mean>0</mean>
                <stddev>0.001</stddev>
              </noise>
            </vertical>
          </position_sensing>
        </gps>
        <plugin name='gps_controller' filename='libgazebo_ros_gps_sensor.so'>
          <ros>
            <remapping>~/out:=/gps/fix</remapping>
          </ros>
          <frame_name>gps_link</frame_name>
        </plugin>
        <pose>0 0 0.43479 0 -0 0</pose>
      </sensor>
      <gravity>1</gravity>
      <sensor name='imu_sensor' type='imu'>
        <always_on>1</always_on>
        <update_rate>100</update_rate>
        <visualize>1</visualize>
        <topic>__default_topic__</topic>
        <plugin name='imu_plugin' filename='libgazebo_ros_imu_sensor.so'>
          <topicName>imu</topicName>
          <bodyName>imu_link</bodyName>
          <updateRateHZ>10.0</updateRateHZ>
          <gaussianNoise>0.0</gaussianNoise>
          <xyzOffset>0 0 0</xyzOffset>
          <rpyOffset>0 0 0</rpyOffset>
          <frame_name>imu_link</frame_name>
          <initialOrientationAsReference>0</initialOrientationAsReference>
        </plugin>
        <pose>0 0 0.53479 0 -0 0</pose>
      </sensor>
      <sensor name='left_camera' type='camera'>
        <always_on>1</always_on>
        <update_rate>30</update_rate>
        <visualize>0</visualize>
        <camera name='left_camera'>
          <horizontal_fov>1.9</horizontal_fov>
          <image>
            <width>640</width>
            <height>480</height>
            <format>R8G8B8</format>
          </image>
          <clip>
            <near>0.02</near>
            <far>300</far>
          </clip>
          <noise>
            <type>gaussian</type>
            <mean>0</mean>
            <stddev>0.007</stddev>
          </noise>
          <distortion>
            <k1>-0.279817</k1>
            <k2>0.060321</k2>
            <k3>0.000487</k3>
            <p1>0.00031</p1>
            <p2>0</p2>
            <center>0.5 0.5</center>
          </distortion>
        </camera>
        <plugin name='left_camera_controller' filename='libgazebo_ros_camera.so'>
          <cameraName>left_camera</cameraName>
          <imageTopicName>image_raw</imageTopicName>
          <cameraInfoTopicName>camera_info</cameraInfoTopicName>
          <frameName>camera_optical_frame</frameName>
          <distortionK1>-0.279817</distortionK1>
          <distortionK2>0.060321</distortionK2>
          <distortionK3>0.000487</distortionK3>
          <distortionT1>0.000310</distortionT1>
          <distortionT2>0.000000</distortionT2>
        </plugin>
        <pose>0 0.242 0.86979 0 -0 1.5708</pose>
      </sensor>
      <sensor name='right_camera' type='camera'>
        <always_on>1</always_on>
        <update_rate>30</update_rate>
        <visualize>0</visualize>
        <camera name='right_camera'>
          <horizontal_fov>1.9</horizontal_fov>
          <image>
            <width>640</width>
            <height>480</height>
            <format>R8G8B8</format>
          </image>
          <clip>
            <near>0.02</near>
            <far>300</far>
          </clip>
          <noise>
            <type>gaussian</type>
            <mean>0</mean>
            <stddev>0.007</stddev>
          </noise>
          <distortion>
            <k1>-0.279817</k1>
            <k2>0.060321</k2>
            <k3>0.000487</k3>
            <p1>0.00031</p1>
            <p2>0</p2>
            <center>0.5 0.5</center>
          </distortion>
        </camera>
        <plugin name='right_camera_controller' filename='libgazebo_ros_camera.so'>
          <cameraName>right_camera</cameraName>
          <imageTopicName>image_raw</imageTopicName>
          <cameraInfoTopicName>camera_info</cameraInfoTopicName>
          <frameName>camera_optical_frame</frameName>
          <distortionK1>-0.279817</distortionK1>
          <distortionK2>0.060321</distortionK2>
          <distortionK3>0.000487</distortionK3>
          <distortionT1>0.000310</distortionT1>
          <distortionT2>0.000000</distortionT2>
        </plugin>
        <pose>0 -0.241 0.86979 0 0 -1.5708</pose>
      </sensor>
      <sensor name='ydlidar_sensor' type='ray'>
        <visualize>0</visualize>
        <update_rate>40</update_rate>
        <ray>
          <scan>
            <horizontal>
              <samples>400</samples>
              <resolution>1</resolution>
              <min_angle>-3.14159</min_angle>
              <max_angle>3.14159</max_angle>
            </horizontal>
          </scan>
          <range>
            <min>0.12</min>
            <max>16</max>
            <resolution>0.01</resolution>
          </range>
          <noise>
            <type>gaussian</type>
            <mean>0</mean>
            <stddev>0.01</stddev>
          </noise>
        </ray>
        <plugin name='gazebo_ros_ydlidar_controller' filename='libgazebo_ros_ray_sensor.so'>
          <ros>
            <argument>~/out:=scan</argument>
          </ros>
          <output_type>sensor_msgs/LaserScan</output_type>
          <frame_name>ydlidar_link</frame_name>
        </plugin>
        <pose>0.25 0 0.41479 0 -0 0</pose>
      </sensor>
      <sensor name='zed2_center_camera' type='camera'>
        <always_on>1</always_on>
        <update_rate>30</update_rate>
        <visualize>0</visualize>
        <camera name='zed2_center_camera'>
          <horizontal_fov>1.9</horizontal_fov>
          <image>
            <width>640</width>
            <height>480</height>
            <format>R8G8B8</format>
          </image>
          <clip>
            <near>0.02</near>
            <far>300</far>
          </clip>
          <noise>
            <type>gaussian</type>
            <mean>0</mean>
            <stddev>0.007</stddev>
          </noise>
          <distortion>
            <k1>-0.279817</k1>
            <k2>0.060321</k2>
            <k3>0.000487</k3>
            <p1>0.00031</p1>
            <p2>0</p2>
            <center>0.5 0.5</center>
          </distortion>
        </camera>
        <plugin name='zed2_center_camera_controller' filename='libgazebo_ros_camera.so'>
          <cameraName>camera</cameraName>
          <imageTopicName>image_raw</imageTopicName>
          <cameraInfoTopicName>camera_info</cameraInfoTopicName>
          <frameName>camera_optical_frame</frameName>
          <distortionK1>-0.279817</distortionK1>
          <distortionK2>0.060321</distortionK2>
          <distortionK3>0.000487</distortionK3>
          <distortionT1>0.000310</distortionT1>
          <distortionT2>0.000000</distortionT2>
        </plugin>
        <pose>0.36 0 0.34479 0 -0 0</pose>
      </sensor>
      <sensor name='zed2_left_raw_camera' type='camera'>
        <always_on>1</always_on>
        <update_rate>15</update_rate>
        <visualize>0</visualize>
        <camera name='zed2_left_raw'>
          <horizontal_fov>1.7633</horizontal_fov>
          <image>
            <width>1280</width>
            <height>720</height>
            <format>R8G8B8</format>
          </image>
          <clip>
            <near>0.02</near>
            <far>300</far>
          </clip>
          <noise>
            <type>gaussian</type>
            <mean>0</mean>
            <stddev>0.007</stddev>
          </noise>
          <distortion>
            <k1>-0.0436936</k1>
            <k2>0.0146165</k2>
            <p1>-0.00657332</p1>
            <p2>-0.0002169</p2>
            <k3>8.4328e-05</k3>
            <center>0.5 0.5</center>
          </distortion>
        </camera>
        <plugin name='zed2_left_camera_controller' filename='libgazebo_ros_camera.so'>
          <cameraName>zed2/left_raw</cameraName>
          <imageTopicName>image_raw_color</imageTopicName>
          <cameraInfoTopicName>camera_info</cameraInfoTopicName>
          <frameName>zed2_left_camera_optical_frame</frameName>
          <distortionK1>-0.043693598</distortionK1>
          <distortionK2>0.0146164996</distortionK2>
          <distortionT1>-0.006573319</distortionT1>
          <distortionT2>-0.000216900</distortionT2>
          <distortionK3>0.000084328</distortionK3>
          <CxPrime>648.5</CxPrime>
          <Cx>648.5</Cx>
          <Cy>366.8340148925781</Cy>
          <hackBaseline>0.0</hackBaseline>
        </plugin>
        <pose>0.36 0.06 0.34479 0 -0 0</pose>
      </sensor>
      <sensor name='zed2_leftd_camera' type='depth'>
        <always_on>1</always_on>
        <update_rate>15</update_rate>
        <visualize>0</visualize>
        <camera name='zed2_left'>
          <horizontal_fov>1.7633</horizontal_fov>
          <image>
            <width>1280</width>
            <height>720</height>
            <format>B8G8R8</format>
          </image>
          <clip>
            <near>0.02</near>
            <far>300</far>
          </clip>
          <noise>
            <type>gaussian</type>
            <mean>0</mean>
            <stddev>0.007</stddev>
          </noise>
        </camera>
        <plugin name='zed2_leftd_camera_controller' filename='libgazebo_ros_camera.so'>
          <frame_name>zed2_left_camera_optical_frame</frame_name>
          <cameraName>zed2</cameraName>
          <imageTopicName>left/image_rect_color</imageTopicName>
          <cameraInfoTopicName>left/camera_info</cameraInfoTopicName>
          <depthImageTopicName>depth/depth_registered</depthImageTopicName>
          <depthImageInfoTopicName>depth/camera_info</depthImageInfoTopicName>
          <pointCloudTopicName>point_cloud/cloud_registered</pointCloudTopicName>
          <pointCloudCutoff>0.3</pointCloudCutoff>
          <pointCloudCutoffMax>20.0</pointCloudCutoffMax>
          <baseline>0.12</baseline>
          <CxPrime>658.8206787109375</CxPrime>
          <Cx>658.8206787109375</Cx>
          <Cy>372.25787353515625</Cy>
          <hackBaseline>0.0</hackBaseline>
        </plugin>
        <pose>0.36 0.06 0.34479 0 -0 0</pose>
      </sensor>
      <sensor name='zed2_right_raw_camera' type='camera'>
        <always_on>1</always_on>
        <update_rate>15</update_rate>
        <visualize>0</visualize>
        <camera name='zed2_right_raw'>
          <horizontal_fov>1.7633</horizontal_fov>
          <image>
            <width>1280</width>
            <height>720</height>
            <format>R8G8B8</format>
          </image>
          <clip>
            <near>0.02</near>
            <far>300</far>
          </clip>
          <noise>
            <type>gaussian</type>
            <mean>0</mean>
            <stddev>0.007</stddev>
          </noise>
          <distortion>
            <k1>-0.0409933</k1>
            <k2>0.00959359</k2>
            <p1>-0.00442985</p1>
            <p2>0.000192024</p2>
            <k3>-0.00032088</k3>
            <center>0.5 0.5</center>
          </distortion>
        </camera>
        <plugin name='zed2_right_camera_controller' filename='libgazebo_ros_camera.so'>
          <cameraName>zed2/right_raw</cameraName>
          <imageTopicName>image_raw_color</imageTopicName>
          <cameraInfoTopicName>camera_info</cameraInfoTopicName>
          <frameName>zed2_right_camera_optical_frame</frameName>
          <distortionK1>-0.040993299</distortionK1>
          <distortionK2>0.009593590</distortionK2>
          <distortionT1>-0.004429849</distortionT1>
          <distortionT2>0.000192024</distortionT2>
          <distortionK3>-0.000320880</distortionK3>
          <CxPrime>659.3049926757812</CxPrime>
          <Cx>659.3049926757812</Cx>
          <Cy>371.39849853515625</Cy>
          <hackBaseline>0.12</hackBaseline>
        </plugin>
        <pose>0.36 -0.06 0.34479 0 -0 0</pose>
      </sensor>
      <sensor name='zed2_right_camera' type='camera'>
        <always_on>1</always_on>
        <update_rate>15</update_rate>
        <visualize>0</visualize>
        <camera name='zed2_right'>
          <horizontal_fov>1.7633</horizontal_fov>
          <image>
            <width>1280</width>
            <height>720</height>
            <format>R8G8B8</format>
          </image>
          <clip>
            <near>0.02</near>
            <far>300</far>
          </clip>
          <noise>
            <type>gaussian</type>
            <mean>0</mean>
            <stddev>0.007</stddev>
          </noise>
        </camera>
        <plugin name='zed2_rightrect_camera_controller' filename='libgazebo_ros_camera.so'>
          <cameraName>zed2/right</cameraName>
          <imageTopicName>image_rect_color</imageTopicName>
          <cameraInfoTopicName>camera_info</cameraInfoTopicName>
          <frameName>zed2_right_camera_optical_frame</frameName>
          <CxPrime>658.8206787109375</CxPrime>
          <Cx>658.8206787109375</Cx>
          <Cy>372.25787353515625</Cy>
          <hackBaseline>0.12</hackBaseline>
        </plugin>
        <pose>0.36 -0.06 0.34479 0 -0 0</pose>
      </sensor>
    </link>
    <joint name='front_left_wheel' type='revolute'>
      <pose relative_to='base_footprint'>0.249 0.29153 0.16459 -3.14119 0 0</pose>
      <parent>base_footprint</parent>
      <child>front_left_wheel_link</child>
      <axis>
        <xyz>0 -1 0</xyz>
        <limit>
          <lower>-1e+16</lower>
          <upper>1e+16</upper>
        </limit>
        <dynamics>
          <spring_reference>0</spring_reference>
          <spring_stiffness>0</spring_stiffness>
        </dynamics>
      </axis>
    </joint>
    <link name='front_left_wheel_link'>
      <pose relative_to='front_left_wheel'>0 0 0 0 -0 0</pose>
      <inertial>
        <pose>0 0 0 0 -0 0</pose>
        <mass>3</mass>
        <inertia>
          <ixx>0.7171</ixx>
          <ixy>0</ixy>
          <ixz>0</ixz>
          <iyy>0.1361</iyy>
          <iyz>0</iyz>
          <izz>0.7171</izz>
        </inertia>
      </inertial>
      <collision name='front_left_wheel_link_collision'>
        <pose>0 0 0 1.57079 -0 0</pose>
        <geometry>
          <cylinder>
            <length>0.11653</length>
            <radius>0.16459</radius>
          </cylinder>
        </geometry>
      </collision>
      <visual name='front_left_wheel_link_visual'>
        <pose>0 0 0 0 -0 0</pose>
        <geometry>
          <mesh>
            <scale>1 1 1</scale>
            <uri>model://parc_robot_description/meshes/wheel_type2.dae</uri>
          </mesh>
        </geometry>
      </visual>
    </link>
    <joint name='front_right_wheel' type='revolute'>
      <pose relative_to='base_footprint'>0.249 -0.29153 0.16459 -3.14119 0 0</pose>
      <parent>base_footprint</parent>
      <child>front_right_wheel_link</child>
      <axis>
        <xyz>0 -1 0</xyz>
        <limit>
          <lower>-1e+16</lower>
          <upper>1e+16</upper>
        </limit>
        <dynamics>
          <spring_reference>0</spring_reference>
          <spring_stiffness>0</spring_stiffness>
        </dynamics>
      </axis>
    </joint>
    <link name='front_right_wheel_link'>
      <pose relative_to='front_right_wheel'>0 0 0 0 -0 0</pose>
      <inertial>
        <pose>0 0 0 0 -0 0</pose>
        <mass>3</mass>
        <inertia>
          <ixx>0.7171</ixx>
          <ixy>0</ixy>
          <ixz>0</ixz>
          <iyy>0.1361</iyy>
          <iyz>0</iyz>
          <izz>0.7171</izz>
        </inertia>
      </inertial>
      <collision name='front_right_wheel_link_collision'>
        <pose>0 0 0 1.57079 -0 0</pose>
        <geometry>
          <cylinder>
            <length>0.11653</length>
            <radius>0.16459</radius>
          </cylinder>
        </geometry>
      </collision>
      <visual name='front_right_wheel_link_visual'>
        <pose>0 0 0 0 -0 0</pose>
        <geometry>
          <mesh>
            <scale>1 1 1</scale>
            <uri>model://parc_robot_description/meshes/wheel_type1.dae</uri>
          </mesh>
        </geometry>
      </visual>
    </link>
    <joint name='rear_left_wheel' type='revolute'>
      <pose relative_to='base_footprint'>-0.249 0.29153 0.16459 -3.14119 0 0</pose>
      <parent>base_footprint</parent>
      <child>rear_left_wheel_link</child>
      <axis>
        <xyz>0 -1 0</xyz>
        <limit>
          <lower>-1e+16</lower>
          <upper>1e+16</upper>
        </limit>
        <dynamics>
          <spring_reference>0</spring_reference>
          <spring_stiffness>0</spring_stiffness>
        </dynamics>
      </axis>
    </joint>
    <link name='rear_left_wheel_link'>
      <pose relative_to='rear_left_wheel'>0 0 0 0 -0 0</pose>
      <inertial>
        <pose>0 0 0 0 -0 0</pose>
        <mass>3</mass>
        <inertia>
          <ixx>0.7171</ixx>
          <ixy>0</ixy>
          <ixz>0</ixz>
          <iyy>0.1361</iyy>
          <iyz>0</iyz>
          <izz>0.7171</izz>
        </inertia>
      </inertial>
      <collision name='rear_left_wheel_link_collision'>
        <pose>0 0 0 1.57079 -0 0</pose>
        <geometry>
          <cylinder>
            <length>0.11653</length>
            <radius>0.16459</radius>
          </cylinder>
        </geometry>
      </collision>
      <visual name='rear_left_wheel_link_visual'>
        <pose>0 0 0 0 -0 0</pose>
        <geometry>
          <mesh>
            <scale>1 1 1</scale>
            <uri>model://parc_robot_description/meshes/wheel_type1.dae</uri>
          </mesh>
        </geometry>
      </visual>
    </link>
    <joint name='rear_right_wheel' type='revolute'>
      <pose relative_to='base_footprint'>-0.249 -0.29153 0.16459 -3.14119 0 0</pose>
      <parent>base_footprint</parent>
      <child>rear_right_wheel_link</child>
      <axis>
        <xyz>0 -1 0</xyz>
        <limit>
          <lower>-1e+16</lower>
          <upper>1e+16</upper>
        </limit>
        <dynamics>
          <spring_reference>0</spring_reference>
          <spring_stiffness>0</spring_stiffness>
        </dynamics>
      </axis>
    </joint>
    <link name='rear_right_wheel_link'>
      <pose relative_to='rear_right_wheel'>0 0 0 0 -0 0</pose>
      <inertial>
        <pose>0 0 0 0 -0 0</pose>
        <mass>3</mass>
        <inertia>
          <ixx>0.7171</ixx>
          <ixy>0</ixy>
          <ixz>0</ixz>
          <iyy>0.1361</iyy>
          <iyz>0</iyz>
          <izz>0.7171</izz>
        </inertia>
      </inertial>
      <collision name='rear_right_wheel_link_collision'>
        <pose>0 0 0 1.57079 -0 0</pose>
        <geometry>
          <cylinder>
            <length>0.11653</length>
            <radius>0.16459</radius>
          </cylinder>
        </geometry>
      </collision>
      <visual name='rear_right_wheel_link_visual'>
        <pose>0 0 0 0 -0 0</pose>
        <geometry>
          <mesh>
            <scale>1 1 1</scale>
            <uri>model://parc_robot_description/meshes/wheel_type2.dae</uri>
          </mesh>
        </geometry>
      </visual>
    </link>
    <static>0</static>
    <plugin name='gazebo_ros2_control' filename='libgazebo_ros2_control.so'>
      <parameters>/home/noobinventor/parc_ws/install/parc_robot_bringup/share/parc_robot_bringup/config/controllers.yaml</parameters>
      <parameters>/home/noobinventor/parc_ws/install/parc_robot_bringup/share/parc_robot_bringup/config/gazebo_ros2_ctl_use_sim.yaml</parameters>
    </plugin>
  </model>
</sdf>
